Workbook

Sheet ATR29_Raw_Data
A1: Summary
A2: Study Name | B2: ATR 29. Ventnor Avenue, between Trenton Avenue & Black Horse Pike
A3: Project | B3: SJTPO: T-1030051: Data Collection Program
A4: Project Code | B4: T-1030051
A5: Channel Granularity | B5: By Direction
A6: Bin Size | B6: 1 hour
A7: Time Zone | B7: America/New_York
A8: Start Time | B8: 46144
A9: End Time | B9: 46151
A10: Location | B10: SJTPO ATR 29
A11: Latitude and Longitude | B11: 39.350997,-74.455805
A13: Midday Peak (WKND) | B13: May 02 2026 11:15AM - 12:15 PM (0.934)
A14: PM Peak (WKND) | B14: May 02 2026 3PM - 4 PM (0.939)
A15: AM Peak (WKND) | B15: May 03 2026 10AM - 11 AM (0.916)
A16: Midday Peak | B16: May 05 2026 12:30PM - 1:30 PM (0.915)
A17: AM Peak | B17: May 06 2026 7:45AM - 8:45 AM (0.883)
A18: PM Peak (Overall Peak Hour) | B18: May 08 2026 2:45PM - 3:45 PM (0.964)
A19: Motorcycles
A20: Entry | B20: n/a | C20: n/a
A21: Direction | B21: Northbound | C21: Southbound
A22: Start Time | B22: Thru | C22: Thru
A23: 46144 | B23: 0 | C23: 0
A24: 46144.042 | B24: 0 | C24: 0
A25: 46144.083 | B25: 0 | C25: 0
A26: 46144.125 | B26: 0 | C26: 0
A27: 46144.167 | B27: 0 | C27: 0
A28: 46144.208 | B28: 0 | C28: 0
A29: 46144.25 | B29: 0 | C29: 1
A30: 46144.292 | B30: 1 | C30: 0
A31: 46144.333 | B31: 0 | C31: 0
A32: 46144.375 | B32: 0 | C32: 0
A33: 46144.417 | B33: 0 | C33: 0
A34: 46144.458 | B34: 0 | C34: 2
... A190: 46150.958 | B190: 0 | C190: 0
A191: Lights
A192: Entry | B192: n/a | C192: n/a
A193: Direction | B193: Northbound | C193: Southbound
A194: Start Time | B194: Thru | C194: Thru
A195: 46144 | B195: 117 | C195: 107
A196: 46144.042 | B196: 83 | C196: 78
...

Sheet ATR29_Raw_Clean
A1: Summary
A2: Study Name | B2: ATR 29. Ventnor Avenue, between Trenton Avenue & Black Horse Pike
A3: Project | B3: SJTPO: T-1030051: Data Collection Program
A4: Project Code | B4: T-1030051
A5: Channel Granularity | B5: By Direction
A6: Bin Size | B6: 1 hour
A7: Time Zone | B7: America/New_York
A8: Start Time | B8: 46144
A9: End Time | B9: 46151
A10: Location | B10: SJTPO ATR 29
A11: Latitude and Longitude | B11: 39.350997,-74.455805
A13: Midday Peak (WKND) | B13: May 02 2026 11:15AM - 12:15 PM (0.934)
A14: PM Peak (WKND) | B14: May 02 2026 3PM - 4 PM (0.939)
A15: AM Peak (WKND) | B15: May 03 2026 10AM - 11 AM (0.916)
A16: Midday Peak | B16: May 05 2026 12:30PM - 1:30 PM (0.915)
A17: AM Peak | B17: May 06 2026 7:45AM - 8:45 AM (0.883)
A18: PM Peak (Overall Peak Hour) | B18: May 08 2026 2:45PM - 3:45 PM (0.964)
A22: Date | B22: NB_Counts | C22: SB_Counts | D22: Class | E22: NBSB_Counts | G22: Sum_NB | H22: Sum_SB | J22: Sum_NBSB
A23: 46144 | B23: =ATR29_Raw_Data!B23 -> 0 | C23: =ATR29_Raw_Data!C23 -> 0 | D23: Motorcycles | E23: =SUM(B23:C23) -> 0 | G23: =SUM(B23:B1030) -> 52523 | H23: =SUM(C23:C1030) -> 29806 | J23: =SUM(E23:E1030) -> 82329
A24: 46144.042 | B24: =ATR29_Raw_Data!B24 -> 0 | C24: =ATR29_Raw_Data!C24 -> 0 | D24: Motorcycles | E24: =SUM(B24:C24) -> 0
A25: 46144.083 | B25: =ATR29_Raw_Data!B25 -> 0 | C25: =ATR29_Raw_Data!C25 -> 0 | D25: Motorcycles | E25: =SUM(B25:C25) -> 0
A26: 46144.125 | B26: =ATR29_Raw_Data!B26 -> 0 | C26: =ATR29_Raw_Data!C26 -> 0 | D26: Motorcycles | E26: =SUM(B26:C26) -> 0
A27: 46144.167 | B27: =ATR29_Raw_Data!B27 -> 0 | C27: =ATR29_Raw_Data!C27 -> 0 | D27: Motorcycles | E27: =SUM(B27:C27) -> 0
A28: 46144.208 | B28: =ATR29_Raw_Data!B28 -> 0 | C28: =ATR29_Raw_Data!C28 -> 0 | D28: Motorcycles | E28: =SUM(B28:C28) -> 0
A29: 46144.25 | B29: =ATR29_Raw_Data!B29 -> 0 | C29: =ATR29_Raw_Data!C29 -> 1 | D29: Motorcycles | E29: =SUM(B29:C29) -> 1
A30: 46144.292 | B30: =ATR29_Raw_Data!B30 -> 1 | C30: =ATR29_Raw_Data!C30 -> 0 | D30: Motorcycles | E30: =SUM(B30:C30) -> 1
A31: 46144.333 | B31: =ATR29_Raw_Data!B31 -> 0 | C31: =ATR29_Raw_Data!C31 -> 0 | D31: Motorcycles | E31: =SUM(B31:C31) -> 0
A32: 46144.375 | B32: =ATR29_Raw_Data!B32 -> 0 | C32: =ATR29_Raw_Data!C32 -> 0 | D32: Motorcycles | E32: =SUM(B32:C32) -> 0
A33: 46144.417 | B33: =ATR29_Raw_Data!B33 -> 0 | C33: =ATR29_Raw_Data!C33 -> 0 | D33: Motorcycles | E33: =SUM(B33:C33) -> 0
A34: 46144.458 | B34: =ATR29_Raw_Data!B34 -> 0 | C34: =ATR29_Raw_Data!C34 -> 2 | D34: Motorcycles | E34: =SUM(B34:C34) -> 2
A35: 46144.5 | B35: =ATR29_Raw_Data!B35 -> 0 | C35: =ATR29_Raw_Data!C35 -> 0 | D35: Motorcycles | E35: =SUM(B35:C35) -> 0
... A190: 46150.958 | B190: =ATR29_Raw_Data!B190 -> 0 | C190: =ATR29_Raw_Data!C190 -> 0 | D190: Motorcycles | E190: =SUM(B190:C190) -> 0
A191: 46144 | B191: =ATR29_Raw_Data!B195 -> 117 | C191: =ATR29_Raw_Data!C195 -> 107 | D191: Lights | E191: =SUM(B191:C191) -> 224
A192: 46144.042 | B192: =ATR29_Raw_Data!B196 -> 83 | C192: =ATR29_Raw_Data!C196 -> 78 | D192: Lights | E192: =SUM(B192:C192) -> 161
A193: 46144.083 | B193: =ATR29_Raw_Data!B197 -> 57 | C193: =ATR29_Raw_Data!C197 -> 67 | D193: Lights | E193: =SUM(B193:C193) -> 124
A194: 46144.125 | B194: =ATR29_Raw_Data!B198 -> 45 | C194: =ATR29_Raw_Data!C198 -> 40 | D194: Lights | E194: =SUM(B194:C194) -> 85
A195: 46144.167 | B195: =ATR29_Raw_Data!B199 -> 54 | C195: =ATR29_Raw_Data!C199 -> 31 | D195: Lights | E195: =SUM(B195:C195) -> 85
A196: 46144.208 | B196: =ATR29_Raw_Data!B200 -> 60 | C196: =ATR29_Raw_Data!C200 -> 23 | D196: Lights | E196: =SUM(B196:C196) -> 83
A197: 46144.25 | B197: =ATR29_Raw_Data!B201 -> 144 | C197: =ATR29_Raw_Data!C201 -> 54 | D197: Lights | E197: =SUM(B197:C197) -> 198
A198: 46144.292 | B198: =ATR29_Raw_Data!B202 -> 209 | C198: =ATR29_Raw_Data!C202 -> 112 | D198: Lights | E198: =SUM(B198:C198) -> 321
...

Sheet ATR29_ADT_by_Class
A2: Pivot Table | G2: Count Sum by Class | M2: %Count by Class
A3: Class | B3: Sum of NBSB_Counts | C3: Sum of NB_Counts | D3: Sum of SB_Counts | G3: Class | H3: Sum_NBSB_Counts | I3: Sum_NB_Count | J3: Sum_SB_Count | M3: Class | N3: NBSB_Counts | O3: NB_Count | P3: SB_Count
A4: Motorcycles | B4: 126 | C4: 70 | D4: 56 | G4: Motorcycles | H4: 135 | I4: 69 | J4: 66 | M4: Motorcycles | N4: =(H4/$H$10) -> 0.0015684179 | O4: =(I4/$I$10) -> 0.001501861 | P4: =(J4/$J$10) -> 0.0016446139
A5: Lights | B5: 76025 | C5: 48371 | D5: 27654 | G5: Lights | H5: 81905 | I5: 43794 | J5: 38111 | M5: Lights | N5: =(H5/$H$10) -> 0.95156493 | O5: =(I5/$I$10) -> 0.95322465 | P5: =(J5/$J$10) -> 0.94966485
A6: SU_Truck | B6: 1002 | C6: 525 | D6: 477 | G6: SU_Truck | H6: 3077 | I6: 1680 | J6: 1397 | M6: SU_Truck | N6: =(H6/$H$10) -> 0.03574831 | O6: =(I6/$I$10) -> 0.03656705 | P6: =(J6/$J$10) -> 0.034810994
A7: Art_Trucks | B7: 96 | C7: 47 | D7: 49 | G7: Art_Trucks | H7: 615 | I7: 228 | J7: 387 | M7: Art_Trucks | N7: =(H7/$H$10) -> 0.0071450148 | O7: =(I7/$I$10) -> 0.0049626711 | P7: =(J7/$J$10) -> 0.0096434178
A8: Buses | B8: 2540 | C8: 1755 | D8: 785 | G8: Buses | H8: 271 | I8: 131 | J8: 140 | M8: Buses | N8: =(H8/$H$10) -> 0.0031484537 | O8: =(I8/$I$10) -> 0.0028513593 | P8: =(J8/$J$10) -> 0.0034885749
A9: Bicycles | B9: 2540 | C9: 1755 | D9: 785 | G9: Bicycles | H9: 71 | I9: 41 | J9: 30 | M9: Bicycles | N9: =(H9/$H$10) -> 0.00082487162 | O9: =(I9/$I$10) -> 0.00089241016 | P9: =(J9/$J$10) -> 0.00074755177
A10: Grand Total | B10: 82329 | C10: 52523 | D10: 29806 | G10: Grand Total | H10: 86074 | I10: 45943 | J10: 40131 | M10: Grand Total | N10: =SUM(N4:N9) -> 1 | O10: =SUM(O4:O9) -> 1 | P10: =SUM(P4:P9) -> 1
G13: ADT by Class
G14: Class | H14: ADT_NBSB_Counts | I14: ADT_NB_Count | J14: ADT_SB_Count
G15: Motorcycles | H15: =H4/7 -> 19.285714 | I15: =I4/7 -> 9.8571429 | J15: =J4/7 -> 9.4285714
G16: Lights | H16: =H5/7 -> 11700.714 | I16: =I5/7 -> 6256.2857 | J16: =J5/7 -> 5444.4286
G17: SU_Truck | H17: =H6/7 -> 439.57143 | I17: =I6/7 -> 240 | J17: =J6/7 -> 199.57143
G18: Art_Trucks | H18: =H7/7 -> 87.857143 | I18: =I7/7 -> 32.571429 | J18: =J7/7 -> 55.285714
G19: Buses | H19: =H8/7 -> 38.714286 | I19: =I8/7 -> 18.714286 | J19: =J8/7 -> 20
G20: Bicycles | H20: =H9/7 -> 10.142857 | I20: =I9/7 -> 5.8571429 | J20: =J9/7 -> 4.2857143
G21: Spring_ADT | H21: =SUM(H15:H20) -> 12296.286 | I21: =SUM(I15:I20) -> 6563.2857 | J21: =SUM(J15:J20) -> 5733
