Workbook

Sheet ATR33_Raw_Data
A1: Summary
A2: Study Name | B2: ATR 33. NJ 147, N Wildwood Boulevard, West of the Old Wildwood Boulevard Jug Handle
A3: Project | B3: SJTPO: T-1030051: Data Collection Program
A4: Project Code | B4: T-1030051
A5: Channel Granularity | B5: By Lanes
A6: Bin Size | B6: 1 hour
A7: Time Zone | B7: America/New_York
A8: Start Time | B8: 46157
A9: End Time | B9: 46164
A10: Location | B10: SJTPO ATR 33
A11: Latitude and Longitude | B11: 39.032357,-74.821724
A13: PM Peak | B13: May 15 2026 2:15PM - 3:15 PM (0.960)
A14: PM Peak (WKND) | B14: May 16 2026 1:15PM - 2:15 PM (0.940)
A15: AM Peak (WKND) | B15: May 17 2026 10AM - 11 AM (0.864)
A16: Midday Peak (WKND) (Overall Peak Hour) | B16: May 17 2026 11:30AM - 12:30 PM (0.977)
A17: AM Peak | B17: May 21 2026 10AM - 11 AM (0.906)
A18: Midday Peak | B18: May 21 2026 1PM - 2 PM (0.914)
A19: Motorcycles
A20: Entry | B20: n/a | E20: n/a
A21: Direction | B21: Eastbound | E21: Westbound
A22: Start Time | B22: Lane 1 | C22: Lane 2 | D22: Lane 3 | E22: Lane 1 | F22: Lane 2 | H22: EB_Sum | I22: WB_Sum | K22: =SUM(H23:H1048576) -> 52349 | L22: =SUM(I23:I1048576) -> 49560 | M22: =SUM(K21:L22) -> 101909
A23: 46157 | B23: 0 | C23: 0 | D23: 0 | E23: 0 | F23: 0 | H23: =SUM(B23:D23) -> 0 | I23: =SUM(E23:F23) -> 0
A24: 46157.042 | B24: 0 | C24: 0 | D24: 0 | E24: 0 | F24: 0 | H24: =SUM(B24:D24) -> 0 | I24: =SUM(E24:F24) -> 0
A25: 46157.083 | B25: 0 | C25: 0 | D25: 0 | E25: 0 | F25: 0 | H25: =SUM(B25:D25) -> 0 | I25: =SUM(E25:F25) -> 0
A26: 46157.125 | B26: 0 | C26: 0 | D26: 0 | E26: 0 | F26: 0 | H26: =SUM(B26:D26) -> 0 | I26: =SUM(E26:F26) -> 0
A27: 46157.167 | B27: 0 | C27: 0 | D27: 0 | E27: 0 | F27: 0 | H27: =SUM(B27:D27) -> 0 | I27: =SUM(E27:F27) -> 0
A28: 46157.208 | B28: 0 | C28: 0 | D28: 0 | E28: 0 | F28: 0 | H28: =SUM(B28:D28) -> 0 | I28: =SUM(E28:F28) -> 0
A29: 46157.25 | B29: 0 | C29: 0 | D29: 0 | E29: 0 | F29: 0 | H29: =SUM(B29:D29) -> 0 | I29: =SUM(E29:F29) -> 0
A30: 46157.292 | B30: 0 | C30: 0 | D30: 0 | E30: 0 | F30: 0 | H30: =SUM(B30:D30) -> 0 | I30: =SUM(E30:F30) -> 0
A31: 46157.333 | B31: 0 | C31: 1 | D31: 0 | E31: 1 | F31: 0 | H31: =SUM(B31:D31) -> 1 | I31: =SUM(E31:F31) -> 1
A32: 46157.375 | B32: 0 | C32: 0 | D32: 0 | E32: 0 | F32: 0 | H32: =SUM(B32:D32) -> 0 | I32: =SUM(E32:F32) -> 0
A33: 46157.417 | B33: 0 | C33: 0 | D33: 0 | E33: 1 | F33: 0 | H33: =SUM(B33:D33) -> 0 | I33: =SUM(E33:F33) -> 1
A34: 46157.458 | B34: 0 | C34: 0 | D34: 0 | E34: 1 | F34: 0 | H34: =SUM(B34:D34) -> 0 | I34: =SUM(E34:F34) -> 1
... A190: 46163.958 | B190: 0 | C190: 0 | D190: 0 | E190: 0 | F190: 0 | H190: =SUM(B190:D190) -> 0 | I190: =SUM(E190:F190) -> 0
A191: Lights
A192: Entry | B192: n/a | E192: n/a
A193: Direction | B193: Eastbound | E193: Westbound
A194: Start Time | B194: Lane 1 | C194: Lane 2 | D194: Lane 3 | E194: Lane 1 | F194: Lane 2
A195: 46157 | B195: 7 | C195: 19 | D195: 4 | E195: 15 | F195: 2 | H195: =SUM(B195:D195) -> 30 | I195: =SUM(E195:F195) -> 17
A196: 46157.042 | B196: 0 | C196: 17 | D196: 1 | E196: 6 | F196: 5 | H196: =SUM(B196:D196) -> 18 | I196: =SUM(E196:F196) -> 11
...

Sheet ATR33_Raw_Clean
A1: Summary
A2: Study Name | B2: ATR 11. US 322, Black Horse Pike, 500 feet East of Palace Restaurant & Outfitters
A3: Project | B3: SJTPO: T-1030051: Data Collection Program
A4: Project Code | B4: T-1030051
A5: Channel Granularity | B5: By Lanes
A6: Bin Size | B6: 1 hour
A7: Time Zone | B7: America/New_York
A8: Start Time | B8: 46148
A9: End Time | B9: 46155
A10: Location | B10: SJTPO ATR 11
A11: Latitude and Longitude | B11: 39.512313,-74.776581
A13: Midday Peak | B13: May 08 2026 12:15PM - 1:15 PM (0.895)
A14: AM Peak (WKND) | B14: May 09 2026 9AM - 10 AM (0.943)
A15: Midday Peak (WKND) | B15: May 10 2026 12:15PM - 1:15 PM (0.917)
A16: PM Peak (WKND) | B16: May 10 2026 1PM - 2 PM (0.877)
A17: AM Peak | B17: May 12 2026 7:15AM - 8:15 AM (0.904)
A18: PM Peak (Overall Peak Hour) | B18: May 12 2026 4:30PM - 5:30 PM (0.953)
A22: Date | B22: EB_Counts | C22: WB_Counts | D22: Class | E22: EBWB_Counts | H22: EB Total | I22: WB Total | K22: EBWB Total
A23: 46148 | B23: {=ATR33_Raw_Data!H23:H190} -> 0 | C23: {=ATR33_Raw_Data!I23:I190} -> 0 | D23: Motorcycles | E23: =SUM(B23:C23) -> 0 | H23: =SUM(B23:B1030) -> 52349 | I23: =SUM(C23:C1030) -> 49560 | K23: =SUM(E23:E1030) -> 101909
A24: 46148.042 | B24: 0 | C24: 0 | D24: Motorcycles | E24: =SUM(B24:C24) -> 0
A25: 46148.083 | B25: 0 | C25: 0 | D25: Motorcycles | E25: =SUM(B25:C25) -> 0
A26: 46148.125 | B26: 0 | C26: 0 | D26: Motorcycles | E26: =SUM(B26:C26) -> 0
A27: 46148.167 | B27: 0 | C27: 0 | D27: Motorcycles | E27: =SUM(B27:C27) -> 0
A28: 46148.208 | B28: 0 | C28: 0 | D28: Motorcycles | E28: =SUM(B28:C28) -> 0
A29: 46148.25 | B29: 0 | C29: 0 | D29: Motorcycles | E29: =SUM(B29:C29) -> 0
A30: 46148.292 | B30: 0 | C30: 0 | D30: Motorcycles | E30: =SUM(B30:C30) -> 0
A31: 46148.333 | B31: 1 | C31: 1 | D31: Motorcycles | E31: =SUM(B31:C31) -> 2
A32: 46148.375 | B32: 0 | C32: 0 | D32: Motorcycles | E32: =SUM(B32:C32) -> 0
A33: 46148.417 | B33: 0 | C33: 1 | D33: Motorcycles | E33: =SUM(B33:C33) -> 1
A34: 46148.458 | B34: 0 | C34: 1 | D34: Motorcycles | E34: =SUM(B34:C34) -> 1
A35: 46148.5 | B35: 0 | C35: 0 | D35: Motorcycles | E35: =SUM(B35:C35) -> 0
... A190: 46154.958 | B190: 0 | C190: 0 | D190: Motorcycles | E190: =SUM(B190:C190) -> 0
A191: 46148 | B191: {=ATR33_Raw_Data!H195:H362} -> 30 | C191: {=ATR33_Raw_Data!I195:I362} -> 17 | D191: Lights | E191: =SUM(B191:C191) -> 47
A192: 46148.042 | B192: 18 | C192: 11 | D192: Lights | E192: =SUM(B192:C192) -> 29
A193: 46148.083 | B193: 10 | C193: 6 | D193: Lights | E193: =SUM(B193:C193) -> 16
A194: 46148.125 | B194: 7 | C194: 5 | D194: Lights | E194: =SUM(B194:C194) -> 12
A195: 46148.167 | B195: 8 | C195: 23 | D195: Lights | E195: =SUM(B195:C195) -> 31
A196: 46148.208 | B196: 46 | C196: 66 | D196: Lights | E196: =SUM(B196:C196) -> 112
A197: 46148.25 | B197: 115 | C197: 127 | D197: Lights | E197: =SUM(B197:C197) -> 242
A198: 46148.292 | B198: 398 | C198: 319 | D198: Lights | E198: =SUM(B198:C198) -> 717
...

Sheet ATR33_ADT_by_Class
A2: Pivot Table | G2: Count Sum by Class | M2: %Count by Class
A3: Class | B3: Sum of EBWB_Counts | C3: Sum of EB_Counts | D3: Sum of WB_Counts | G3: Class | H3: Sum_EBWB_Counts | I3: Sum_EB_Count | J3: Sum_WB_Count | M3: Class | N3: EBWB_Counts | O3: EB_Count | P3: WB_Count
A4: Motorcycles | B4: 246 | C4: 114 | D4: 132 | G4: Motorcycles | H4: 246 | I4: 114 | J4: 132 | M4: Motorcycles | N4: =(H4/$H$10) -> 0.0024139183 | O4: =(I4/$I$10) -> 0.002177692 | P4: =(J4/$J$10) -> 0.0026634383
A5: Lights | B5: 98835 | C5: 50806 | D5: 48029 | G5: Lights | H5: 98835 | I5: 50806 | J5: 48029 | M5: Lights | N5: =(H5/$H$10) -> 0.96983583 | O5: =(I5/$I$10) -> 0.97052475 | P5: =(J5/$J$10) -> 0.96910815
A6: SU_Truck | B6: 2036 | C6: 1049 | D6: 987 | G6: SU_Truck | H6: 2036 | I6: 1049 | J6: 987 | M6: SU_Truck | N6: =(H6/$H$10) -> 0.019978608 | O6: =(I6/$I$10) -> 0.020038587 | P6: =(J6/$J$10) -> 0.019915254
A7: Art_Trucks | B7: 309 | C7: 171 | D7: 138 | G7: Art_Trucks | H7: 309 | I7: 171 | J7: 138 | M7: Art_Trucks | N7: =(H7/$H$10) -> 0.0030321169 | O7: =(I7/$I$10) -> 0.003266538 | P7: =(J7/$J$10) -> 0.0027845036
A8: Buses | B8: 368 | C8: 163 | D8: 205 | G8: Buses | H8: 368 | I8: 163 | J8: 205 | M8: Buses | N8: =(H8/$H$10) -> 0.0036110648 | O8: =(I8/$I$10) -> 0.0031137175 | P8: =(J8/$J$10) -> 0.0041364003
A9: Bicycles | B9: 115 | C9: 46 | D9: 69 | G9: Bicycles | H9: 115 | I9: 46 | J9: 69 | M9: Bicycles | N9: =(H9/$H$10) -> 0.0011284577 | O9: =(I9/$I$10) -> 0.00087871784 | P9: =(J9/$J$10) -> 0.0013922518
A10: Grand Total | B10: 101909 | C10: 52349 | D10: 49560 | G10: Grand Total | H10: 101909 | I10: 52349 | J10: 49560 | M10: Grand Total | N10: =SUM(N4:N9) -> 1 | O10: =SUM(O4:O9) -> 1 | P10: =SUM(P4:P9) -> 1
G13: ADT by Class
G14: Class | H14: ADT_EBWB_Counts | I14: ADT_EB_Count | J14: ADT_WB_Count
G15: Motorcycles | H15: =H4/7 -> 35.142857 | I15: =I4/7 -> 16.285714 | J15: =J4/7 -> 18.857143
G16: Lights | H16: =H5/7 -> 14119.286 | I16: =I5/7 -> 7258 | J16: =J5/7 -> 6861.2857
G17: SU_Truck | H17: =H6/7 -> 290.85714 | I17: =I6/7 -> 149.85714 | J17: =J6/7 -> 141
G18: Art_Trucks | H18: =H7/7 -> 44.142857 | I18: =I7/7 -> 24.428571 | J18: =J7/7 -> 19.714286
G19: Buses | H19: =H8/7 -> 52.571429 | I19: =I8/7 -> 23.285714 | J19: =J8/7 -> 29.285714
G20: Bicycles | H20: =H9/7 -> 16.428571 | I20: =I9/7 -> 6.5714286 | J20: =J9/7 -> 9.8571429
G21: Spring_ADT | H21: =SUM(H15:H20) -> 14558.429 | I21: =SUM(I15:I20) -> 7478.4286 | J21: =SUM(J15:J20) -> 7080
