Workbook

Sheet ATR38_Raw_Data
A1: Summary
A2: Study Name | B2: ATR 38. Route 40 /322, between Frankfort Court & Toulon Avenue
A3: Project | B3: SJTPO: T-1030051: Data Collection Program
A4: Project Code | B4: T-1030051
A5: Channel Granularity | B5: By Lanes
A6: Bin Size | B6: 1 hour
A7: Time Zone | B7: America/New_York
A8: Start Time | B8: 46149
A9: End Time | B9: 46156
A10: Location | B10: SJTPO ATR 38
A11: Latitude and Longitude | B11: 39.387403,-74.517202
A13: AM Peak (WKND) | B13: May 09 2026 10AM - 11 AM (0.928)
A14: Midday Peak (WKND) | B14: May 09 2026 1PM - 2 PM (0.941)
A15: PM Peak (WKND) | B15: May 09 2026 2:30PM - 3:30 PM (0.893)
A16: AM Peak | B16: May 12 2026 7:45AM - 8:45 AM (0.911)
A17: PM Peak (Overall Peak Hour) | B17: May 12 2026 4:15PM - 5:15 PM (0.938)
A18: Midday Peak | B18: May 13 2026 12:30PM - 1:30 PM (0.957)
A19: Motorcycles
A20: Entry | B20: n/a | E20: n/a
A21: Direction | B21: Eastbound | E21: Westbound
A22: Start Time | B22: Lane 1 | C22: Lane 2 | D22: Lane 3 | E22: Lane 1 | F22: Lane 2 | G22: Lane 3 | H22: EB_Sum | I22: WB_Sum
A23: 46149 | B23: 0 | C23: 0 | D23: 0 | E23: 0 | F23: 0 | G23: 0 | H23: =SUM(B23:D23) -> 0 | I23: =SUM(E23:G23) -> 0
A24: 46149.042 | B24: 0 | C24: 0 | D24: 0 | E24: 0 | F24: 0 | G24: 0 | H24: =SUM(B24:D24) -> 0 | I24: =SUM(E24:G24) -> 0
A25: 46149.083 | B25: 0 | C25: 0 | D25: 0 | E25: 0 | F25: 0 | G25: 0 | H25: =SUM(B25:D25) -> 0 | I25: =SUM(E25:G25) -> 0
A26: 46149.125 | B26: 0 | C26: 0 | D26: 0 | E26: 0 | F26: 0 | G26: 0 | H26: =SUM(B26:D26) -> 0 | I26: =SUM(E26:G26) -> 0
A27: 46149.167 | B27: 0 | C27: 0 | D27: 0 | E27: 0 | F27: 0 | G27: 0 | H27: =SUM(B27:D27) -> 0 | I27: =SUM(E27:G27) -> 0
A28: 46149.208 | B28: 0 | C28: 0 | D28: 0 | E28: 0 | F28: 0 | G28: 0 | H28: =SUM(B28:D28) -> 0 | I28: =SUM(E28:G28) -> 0
A29: 46149.25 | B29: 1 | C29: 1 | D29: 0 | E29: 0 | F29: 0 | G29: 0 | H29: =SUM(B29:D29) -> 2 | I29: =SUM(E29:G29) -> 0
A30: 46149.292 | B30: 0 | C30: 0 | D30: 0 | E30: 0 | F30: 0 | G30: 0 | H30: =SUM(B30:D30) -> 0 | I30: =SUM(E30:G30) -> 0
A31: 46149.333 | B31: 0 | C31: 0 | D31: 0 | E31: 0 | F31: 0 | G31: 0 | H31: =SUM(B31:D31) -> 0 | I31: =SUM(E31:G31) -> 0
A32: 46149.375 | B32: 0 | C32: 0 | D32: 1 | E32: 0 | F32: 0 | G32: 0 | H32: =SUM(B32:D32) -> 1 | I32: =SUM(E32:G32) -> 0
A33: 46149.417 | B33: 0 | C33: 1 | D33: 0 | E33: 1 | F33: 0 | G33: 0 | H33: =SUM(B33:D33) -> 1 | I33: =SUM(E33:G33) -> 1
A34: 46149.458 | B34: 0 | C34: 0 | D34: 0 | E34: 0 | F34: 0 | G34: 0 | H34: =SUM(B34:D34) -> 0 | I34: =SUM(E34:G34) -> 0
... A190: 46155.958 | B190: 0 | C190: 0 | D190: 0 | E190: 0 | F190: 0 | G190: 0 | H190: =SUM(B190:D190) -> 0 | I190: =SUM(E190:G190) -> 0
A191: Lights
A192: Entry | B192: n/a | E192: n/a
A193: Direction | B193: Eastbound | E193: Westbound
A194: Start Time | B194: Lane 1 | C194: Lane 2 | D194: Lane 3 | E194: Lane 1 | F194: Lane 2 | G194: Lane 3
A195: 46149 | B195: 40 | C195: 70 | D195: 3 | E195: 93 | F195: 79 | G195: 1 | H195: =SUM(B195:D195) -> 113 | I195: =SUM(E195:G195) -> 173
A196: 46149.042 | B196: 21 | C196: 35 | D196: 4 | E196: 72 | F196: 32 | G196: 1 | H196: =SUM(B196:D196) -> 60 | I196: =SUM(E196:G196) -> 105
...

Sheet ATR38_Raw_Clean
A1: Summary
A2: Study Name | B2: ATR 36. NJ 52, Howard South Stanton Memorial
A3: Project | B3: SJTPO: T-1030051: Data Collection Program
A4: Project Code | B4: T-1030051
A5: Channel Granularity | B5: By Lanes
A6: Bin Size | B6: 1 hour
A7: Time Zone | B7: America/New_York
A8: Start Time | B8: 46148
A9: End Time | B9: 46154.999
A10: Location | B10: SJTPO ATR 36
A11: Latitude and Longitude | B11: 39.298667,-74.59052
A13: AM Peak | B13: May 08 2026 8:15AM - 9:15 AM (0.955)
A14: Midday Peak | B14: May 08 2026 11:45AM - 12:45 PM (0.941)
A15: PM Peak | B15: May 08 2026 2:45PM - 3:45 PM (0.970)
A16: AM Peak (WKND) | B16: May 10 2026 10AM - 11 AM (0.883)
A17: Midday Peak (WKND) (Overall Peak Hour) | B17: May 10 2026 12:15PM - 1:15 PM (0.955)
A18: PM Peak (WKND) | B18: May 10 2026 1PM - 2 PM (0.948)
A22: Date | B22: EB_Counts | C22: WB_Counts | D22: Class | E22: EBWB_Counts | H22: EB Total | I22: WB Total | K22: EBWB Total
A23: 46149 | B23: {=ATR38_Raw_Data!H23:H190} -> 0 | C23: =ATR38_Raw_Data!I23 -> 0 | D23: Motorcycles | E23: =SUM(B23:C23) -> 0 | H23: =SUM(B23:B1030) -> 92656 | I23: =SUM(C23:C1030) -> 96832 | K23: =SUM(E23:E1030) -> 189488
A24: 46149.042 | B24: 0 | C24: =ATR38_Raw_Data!I24 -> 0 | D24: Motorcycles | E24: =SUM(B24:C24) -> 0
A25: 46149.083 | B25: 0 | C25: =ATR38_Raw_Data!I25 -> 0 | D25: Motorcycles | E25: =SUM(B25:C25) -> 0
A26: 46149.125 | B26: 0 | C26: =ATR38_Raw_Data!I26 -> 0 | D26: Motorcycles | E26: =SUM(B26:C26) -> 0
A27: 46149.167 | B27: 0 | C27: =ATR38_Raw_Data!I27 -> 0 | D27: Motorcycles | E27: =SUM(B27:C27) -> 0
A28: 46149.208 | B28: 0 | C28: =ATR38_Raw_Data!I28 -> 0 | D28: Motorcycles | E28: =SUM(B28:C28) -> 0
A29: 46149.25 | B29: 2 | C29: =ATR38_Raw_Data!I29 -> 0 | D29: Motorcycles | E29: =SUM(B29:C29) -> 2
A30: 46149.292 | B30: 0 | C30: =ATR38_Raw_Data!I30 -> 0 | D30: Motorcycles | E30: =SUM(B30:C30) -> 0
A31: 46149.333 | B31: 0 | C31: =ATR38_Raw_Data!I31 -> 0 | D31: Motorcycles | E31: =SUM(B31:C31) -> 0
A32: 46149.375 | B32: 1 | C32: =ATR38_Raw_Data!I32 -> 0 | D32: Motorcycles | E32: =SUM(B32:C32) -> 1
A33: 46149.417 | B33: 1 | C33: =ATR38_Raw_Data!I33 -> 1 | D33: Motorcycles | E33: =SUM(B33:C33) -> 2
A34: 46149.458 | B34: 0 | C34: =ATR38_Raw_Data!I34 -> 0 | D34: Motorcycles | E34: =SUM(B34:C34) -> 0
A35: 46149.5 | B35: 1 | C35: =ATR38_Raw_Data!I35 -> 0 | D35: Motorcycles | E35: =SUM(B35:C35) -> 1
... A190: 46155.958 | B190: 0 | C190: =ATR38_Raw_Data!I190 -> 0 | D190: Motorcycles | E190: =SUM(B190:C190) -> 0
A191: 46149 | B191: =ATR38_Raw_Data!H195 -> 113 | C191: =ATR38_Raw_Data!I195 -> 173 | D191: Lights | E191: =SUM(B191:C191) -> 286
A192: 46149.042 | B192: =ATR38_Raw_Data!H196 -> 60 | C192: =ATR38_Raw_Data!I196 -> 105 | D192: Lights | E192: =SUM(B192:C192) -> 165
A193: 46149.083 | B193: =ATR38_Raw_Data!H197 -> 40 | C193: =ATR38_Raw_Data!I197 -> 80 | D193: Lights | E193: =SUM(B193:C193) -> 120
A194: 46149.125 | B194: =ATR38_Raw_Data!H198 -> 57 | C194: =ATR38_Raw_Data!I198 -> 88 | D194: Lights | E194: =SUM(B194:C194) -> 145
A195: 46149.167 | B195: =ATR38_Raw_Data!H199 -> 56 | C195: =ATR38_Raw_Data!I199 -> 130 | D195: Lights | E195: =SUM(B195:C195) -> 186
A196: 46149.208 | B196: =ATR38_Raw_Data!H200 -> 121 | C196: =ATR38_Raw_Data!I200 -> 170 | D196: Lights | E196: =SUM(B196:C196) -> 291
A197: 46149.25 | B197: =ATR38_Raw_Data!H201 -> 458 | C197: =ATR38_Raw_Data!I201 -> 395 | D197: Lights | E197: =SUM(B197:C197) -> 853
A198: 46149.292 | B198: =ATR38_Raw_Data!H202 -> 870 | C198: =ATR38_Raw_Data!I202 -> 670 | D198: Lights | E198: =SUM(B198:C198) -> 1540
...

Sheet ATR38_ADT_by_Class
A2: Pivot Table | G2: Count Sum by Class | M2: %Count by Class
A3: Class | B3: Sum of EBWB_Counts | C3: Sum of EB_Counts | D3: Sum of WB_Counts | G3: Class | H3: Sum_EBWB_Counts | I3: Sum_EB_Count | J3: Sum_WB_Count | M3: Class | N3: EBWB_Counts | O3: EB_Count | P3: WB_Count
A4: Motorcycles | B4: 205 | C4: 107 | D4: 98 | G4: Motorcycles | H4: 205 | I4: 107 | J4: 98 | M4: Motorcycles | N4: =(H4/$H$10) -> 0.0010818627 | O4: =(I4/$I$10) -> 0.0011548092 | P4: =(J4/$J$10) -> 0.0010120621
A5: Lights | B5: 184287 | C5: 90164 | D5: 94123 | G5: Lights | H5: 184287 | I5: 90164 | J5: 94123 | M5: Lights | N5: =(H5/$H$10) -> 0.97255235 | O5: =(I5/$I$10) -> 0.97310482 | P5: =(J5/$J$10) -> 0.97202371
A6: SU_Truck | B6: 2501 | C6: 1308 | D6: 1193 | G6: SU_Truck | H6: 2501 | I6: 1308 | J6: 1193 | M6: SU_Truck | N6: =(H6/$H$10) -> 0.013198725 | O6: =(I6/$I$10) -> 0.014116733 | P6: =(J6/$J$10) -> 0.012320307
A7: Art_Trucks | B7: 340 | C7: 156 | D7: 184 | G7: Art_Trucks | H7: 340 | I7: 156 | J7: 184 | M7: Art_Trucks | N7: =(H7/$H$10) -> 0.0017943089 | O7: =(I7/$I$10) -> 0.001683647 | P7: =(J7/$J$10) -> 0.0019001983
A8: Buses | B8: 2040 | C8: 909 | D8: 1131 | G8: Buses | H8: 2040 | I8: 909 | J8: 1131 | M8: Buses | N8: =(H8/$H$10) -> 0.010765853 | O8: =(I8/$I$10) -> 0.0098104818 | P8: =(J8/$J$10) -> 0.011680023
A9: Bicycles | B9: 115 | C9: 12 | D9: 103 | G9: Bicycles | H9: 115 | I9: 12 | J9: 103 | M9: Bicycles | N9: =(H9/$H$10) -> 0.00060689859 | O9: =(I9/$I$10) -> 0.00012951131 | P9: =(J9/$J$10) -> 0.001063698
A10: Grand Total | B10: 189488 | C10: 92656 | D10: 96832 | G10: Grand Total | H10: 189488 | I10: 92656 | J10: 96832 | M10: Grand Total | N10: =SUM(N4:N9) -> 1 | O10: =SUM(O4:O9) -> 1 | P10: =SUM(P4:P9) -> 1
G13: ADT by Class
G14: Class | H14: ADT_EBWB_Counts | I14: ADT_EB_Count | J14: ADT_WB_Count
G15: Motorcycles | H15: =H4/7 -> 29.285714 | I15: =I4/7 -> 15.285714 | J15: =J4/7 -> 14
G16: Lights | H16: =H5/7 -> 26326.714 | I16: =I5/7 -> 12880.571 | J16: =J5/7 -> 13446.143
G17: SU_Truck | H17: =H6/7 -> 357.28571 | I17: =I6/7 -> 186.85714 | J17: =J6/7 -> 170.42857
G18: Art_Trucks | H18: =H7/7 -> 48.571429 | I18: =I7/7 -> 22.285714 | J18: =J7/7 -> 26.285714
G19: Buses | H19: =H8/7 -> 291.42857 | I19: =I8/7 -> 129.85714 | J19: =J8/7 -> 161.57143
G20: Bicycles | H20: =H9/7 -> 16.428571 | I20: =I9/7 -> 1.7142857 | J20: =J9/7 -> 14.714286
G21: Spring_ADT | H21: =SUM(H15:H20) -> 27069.714 | I21: =SUM(I15:I20) -> 13236.571 | J21: =SUM(J15:J20) -> 13833.143
